<mujoco model="canine_pluto">
  <compiler angle="radian" meshdir="meshes/" autolimits="true" inertiafromgeom="false"/>

  <default>
    <joint damping="0.01" armature="0.0" frictionloss="0.0"/>
  </default>

  <asset>
    <mesh name="base_link_1" file="base_link.obj" scale="0.001 0.001 0.001"/>
    <mesh name="FL_Hip_1" file="FL_Hip_1.obj" scale="0.001 0.001 0.001"/>
    <mesh name="FL_thigh_1" file="FL_thigh_1.obj" scale="0.001 0.001 0.001"/>
    <mesh name="FR_Hip_1" file="FR_Hip_1.obj" scale="0.001 0.001 0.001"/>
    <mesh name="FR_thigh_1" file="FR_thigh_1.obj" scale="0.001 0.001 0.001"/>
    <mesh name="HL_Hip_1" file="HL_Hip_1.obj" scale="0.001 0.001 0.001"/>
    <mesh name="HL_thigh_1" file="HL_thigh_1.obj" scale="0.001 0.001 0.001"/>
    <mesh name="HR_Hip_1" file="HR_Hip_1.obj" scale="0.001 0.001 0.001"/>
    <mesh name="HR_thigh_1" file="HR_thigh_1.obj" scale="0.001 0.001 0.001"/>
    <mesh name="HR_calf_1" file="HR_calf_1.obj" scale="0.001 0.001 0.001"/>
  </asset>

  <worldbody>
    <body name="base_link" pos="0 0 0.08">
      <inertial pos="0.0144905 0.000151462 0.144068" quat="0.999881 -0.000505543 -0.0154276 0.000328408" mass="15" diaginertia="0.0422 0.1961 0.2013"/>
      <joint name="floating_base_joint" type="free" limited="false" actuatorfrclimited="false"/>
      <geom type="mesh" rgba="0.502 0.027 0.125 1" mesh="base_link_1"/>
      <body name="FL_hip" pos="0.1935 0.075 0">
        <inertial pos="0.059004 0.0160297 2.21217e-09" quat="0.518189 0.518189 0.481124 0.481124" mass="0.7498" diaginertia="0.00108414 0.000706572 0.00056113"/>
        <joint name="FL_HIP_JOINT" pos="0 0 0" axis="1 0 0"/>
        <geom pos="-0.185613 -0.065216 -0.000494" quat="1 0 0 0" type="mesh" rgba="0.2 0.2 0.2 1" mesh="FL_Hip_1"/>
        <body name="FL_thigh" pos="0.075 -0.003 0">
          <inertial pos="-0.00538772 0.0556427 -0.0265825" quat="0.822371 0.125129 -0.000774627 0.555021" mass="1.539" diaginertia="0.00745448 0.00738798 0.00149755"/>
          <joint name="FL_THIGH_JOINT" pos="0 0 0" axis="0 1 0"/>
          <geom size="0.015 0.0095" pos="0 0.084 -0.23" quat="0.707107 0.707107 0 0" type="cylinder" contype="1" conaffinity="1"/>
          <geom pos="-0.256107 -0.062095 -0.000475" type="mesh" rgba="0.2 0.2 0.2 1" mesh="FL_thigh_1" contype="0" conaffinity="0"/>
          <body name="FL_calf" pos="0 0.085 -0.23">
            <inertial pos="0.0121134 -0.0111121 -0.124984" quat="0.706616 0.00306786 0.00207395 0.707588" mass="0.268" diaginertia="0.00280707 0.00278667 4.42028e-05"/>
            <joint name="FL_KNEE_JOINT" pos="0 0 0" axis="0 1 0"/>
            <geom size="0.025" pos="0 0 -0.23" quat="0.707107 0.707107 0 0" type="sphere" rgba="0.9 0.9 0.9 1" friction="1.0 0.005 0.001" contype="1" conaffinity="1"/>
            <geom pos="0.256221 0.1424 0.230545" quat="1 0 0 0" type="mesh" rgba="0.9 0.9 0.9 1" mesh="HR_calf_1" contype="0" conaffinity="0"/>
          </body>
        </body>
      </body>
      <body name="FR_hip" pos="0.1935 -0.075 0">
        <inertial pos="0.059004 -0.0160297 2.21217e-09" quat="0.481124 0.481124 0.518189 0.518189" mass="0.7498" diaginertia="0.00108414 0.000706572 0.00056113"/>
        <joint name="FR_HIP_JOINT" pos="0 0 0" axis="1 0 0"/>
        <geom pos="-0.185389 0.06478 0.000488" quat="1 0 0 0" type="mesh" rgba="0.2 0.2 0.2 1" mesh="FR_Hip_1"/>
        <body name="FR_thigh" pos="0.075 0.003 0">
          <inertial pos="-0.00538772 -0.0556427 -0.0265825" quat="0.555021 -0.000774627 0.125129 0.822371" mass="1.539" diaginertia="0.00745448 0.00738798 0.00149755"/>
          <joint name="FR_THIGH_JOINT" pos="0 0 0" axis="0 1 0"/>
          <geom size="0.015 0.0095" pos="0 -0.084 -0.23" quat="0.707107 0.707107 0 0" type="cylinder" contype="1" conaffinity="1"/>
          <geom pos="-0.255894 0.061902 0.000472" quat="1 0 0 0" type="mesh" rgba="0.2 0.2 0.2 1" mesh="FR_thigh_1" contype="0" conaffinity="0"/>
          <body name="FR_calf" pos="0 -0.085 -0.23">
            <inertial pos="0.0121134 0.0111121 -0.124984" quat="0.707588 0.00207395 0.00306786 0.706616" mass="0.268" diaginertia="0.00280707 0.00278667 4.42028e-05"/>
            <joint name="FR_KNEE_JOINT" pos="0 0 0" axis="0 1 0"/>
            <geom size="0.025" pos="0 0 -0.23" quat="0.707107 0.707107 0 0" type="sphere" rgba="0.9 0.9 0.9 1" friction="1.0 0.005 0.001" contype="1" conaffinity="1"/>
            <geom pos="0.256221 0.1424 0.230545" quat="1 0 0 0" type="mesh" rgba="0.9 0.9 0.9 1" mesh="HR_calf_1" contype="0" conaffinity="0"/>
          </body>
        </body>
      </body>
      <body name="HL_hip" pos="-0.1935 0.075 0">
        <inertial pos="-0.059004 0.0160297 2.21217e-09" quat="0.481124 0.481124 0.518189 0.518189" mass="0.7498" diaginertia="0.00108414 0.000706572 0.00056113"/>
        <joint name="HL_HIP_JOINT" pos="0 0 0" axis="1 0 0"/>
        <geom pos="0.185387 -0.065854 -0.000501" quat="1 0 0 0" type="mesh" rgba="0.2 0.2 0.2 1" mesh="HL_Hip_1"/>
        <body name="HL_thigh" pos="-0.075 -0.003 0">
          <inertial pos="0.00538772 0.0556427 -0.0265825" quat="0.555021 0.000774627 -0.125129 0.822371" mass="1.539" diaginertia="0.00745448 0.00738798 0.00149755"/>
          <joint name="HL_THIGH_JOINT" pos="0 0 0" axis="0 1 0"/>
          <geom size="0.015 0.0095" pos="0 0.084 -0.23" quat="0.707107 0.707107 0 0" type="cylinder" contype="1" conaffinity="1"/>
          <geom pos="0.255892 -0.062976 -0.000485" type="mesh" rgba="0.2 0.2 0.2 1" mesh="HL_thigh_1" contype="0" conaffinity="0"/>
          <body name="HL_calf" pos="0 0.085 -0.23">
            <inertial pos="-0.0121134 -0.0111121 -0.124984" quat="0.707588 -0.00207395 -0.00306786 0.706616" mass="0.268" diaginertia="0.00280707 0.00278667 4.42028e-05"/>
            <joint name="HL_KNEE_JOINT" pos="0 0 0" axis="0 1 0"/>
            <geom size="0.025" pos="0 0 -0.23" quat="0.707107 0.707107 0 0" type="sphere" rgba="0.9 0.9 0.9 1" friction="1.0 0.005 0.001" contype="1" conaffinity="1"/>
            <geom pos="0.256221 0.1424 0.230545" quat="1 0 0 0" type="mesh" rgba="0.9 0.9 0.9 1" mesh="HR_calf_1" contype="0" conaffinity="0"/>
          </body>
        </body>
      </body>
      <body name="HR_hip" pos="-0.1935 -0.075 0">
        <inertial pos="-0.059004 -0.0160297 2.21217e-09" quat="0.518189 0.518189 0.481124 0.481124" mass="0.7498" diaginertia="0.00108414 0.000706572 0.00056113"/>
        <joint name="HR_HIP_JOINT" pos="0 0 0" axis="1 0 0"/>
        <geom pos="0.185611 0.064142 0.000481" quat="1 0 0 0" type="mesh" rgba="0.2 0.2 0.2 1" mesh="HR_Hip_1"/>
        <body name="HR_thigh" pos="-0.075 0.003 0">
          <inertial pos="0.00538772 -0.0556427 -0.0265825" quat="0.822371 -0.125129 0.000774627 0.555021" mass="1.539" diaginertia="0.00745448 0.00738798 0.00149755"/>
          <joint name="HR_THIGH_JOINT" pos="0 0 0" axis="0 1 0"/>
          <geom size="0.015 0.0095" pos="0 -0.084 -0.23" quat="0.707107 0.707107 0 0" type="cylinder" contype="1" conaffinity="1"/>
          <geom pos="0.256105 0.06102 0.000462" type="mesh" rgba="0.2 0.2 0.2 1" mesh="HR_thigh_1" contype="0" conaffinity="0"/>
          <body name="HR_calf" pos="0 -0.085 -0.23">
            <inertial pos="-0.0121134 0.0111121 -0.124984" quat="0.706616 -0.00306786 -0.00207395 0.707588" mass="0.268" diaginertia="0.00280707 0.00278667 4.42028e-05"/>
            <joint name="HR_KNEE_JOINT" pos="0 0 0" axis="0 1 0"/>
            <geom size="0.025" pos="0 0 -0.23" quat="0.707107 0.707107 0 0" type="sphere" rgba="0.9 0.9 0.9 1" friction="1.0 0.005 0.001" contype="1" conaffinity="1"/>
            <geom pos="0.256221 0.1424 0.230545" quat="1 0 0 0" type="mesh" rgba="0.9 0.9 0.9 1" mesh="HR_calf_1" contype="0" conaffinity="0"/>
          </body>
        </body>
      </body>
    </body>
  </worldbody>
  <actuator>
    <motor name="FL_HIP_JOINT" joint="FL_HIP_JOINT"/>
    <motor name="FL_THIGH_JOINT" joint="FL_THIGH_JOINT"/>
    <motor name="FL_KNEE_JOINT" joint="FL_KNEE_JOINT"/>
    <motor name="FR_HIP_JOINT" joint="FR_HIP_JOINT"/>
    <motor name="FR_THIGH_JOINT" joint="FR_THIGH_JOINT"/>
    <motor name="FR_KNEE_JOINT" joint="FR_KNEE_JOINT"/>
    <motor name="HL_HIP_JOINT" joint="HL_HIP_JOINT"/>
    <motor name="HL_THIGH_JOINT" joint="HL_THIGH_JOINT"/>
    <motor name="HL_KNEE_JOINT" joint="HL_KNEE_JOINT"/>
    <motor name="HR_HIP_JOINT" joint="HR_HIP_JOINT"/>
    <motor name="HR_THIGH_JOINT" joint="HR_THIGH_JOINT"/>
    <motor name="HR_KNEE_JOINT" joint="HR_KNEE_JOINT"/>
  </actuator>
</mujoco>
